2025-09-03 14:48:00,020 INFO    MainThread:14035 [wandb_setup.py:_flush():81] Current SDK version is 0.21.3
2025-09-03 14:48:00,020 INFO    MainThread:14035 [wandb_setup.py:_flush():81] Configure stats pid to 14035
2025-09-03 14:48:00,020 INFO    MainThread:14035 [wandb_setup.py:_flush():81] Loading settings from /Users/gurmannnpreet/.config/wandb/settings
2025-09-03 14:48:00,020 INFO    MainThread:14035 [wandb_setup.py:_flush():81] Loading settings from /Users/gurmannnpreet/Documents/CODING/rl2048/wandb/settings
2025-09-03 14:48:00,020 INFO    MainThread:14035 [wandb_setup.py:_flush():81] Loading settings from environment variables
2025-09-03 14:48:00,021 INFO    MainThread:14035 [wandb_init.py:setup_run_log_directory():686] Logging user logs to /Users/gurmannnpreet/Documents/CODING/rl2048/wandb/run-20250903_144800-0yyd546b/logs/debug.log
2025-09-03 14:48:00,021 INFO    MainThread:14035 [wandb_init.py:setup_run_log_directory():687] Logging internal logs to /Users/gurmannnpreet/Documents/CODING/rl2048/wandb/run-20250903_144800-0yyd546b/logs/debug-internal.log
2025-09-03 14:48:00,027 INFO    MainThread:14035 [wandb_init.py:init():813] calling init triggers
2025-09-03 14:48:00,027 INFO    MainThread:14035 [wandb_init.py:init():818] wandb.init called with sweep_config: {}
config: {'env': {'size': 4, 'target': 2048, 'spawn_prob_2': 0.9}, 'seed': 42, 'agent': {'hidden_dim': 128, 'gamma': 0.99, 'tau': 0.005, 'lr': 0.0003, 'alpha': None}, 'buffer': {'capacity': 200000}, 'train': {'steps': 200000, 'batch_size': 128, 'train_freq': 1, 'gradient_steps': 1, 'eval_interval': 40000, 'eval_max_steps': 5000}, 'reward': {'scale': 0.1, 'invalid_move_penalty': -0.5}, 'wandb': {'enabled': True, 'project': 'rl2048', 'entity': None, 'mode': 'online'}, '_wandb': {}}
2025-09-03 14:48:00,027 INFO    MainThread:14035 [wandb_init.py:init():854] starting backend
2025-09-03 14:48:00,254 INFO    MainThread:14035 [wandb_init.py:init():857] sending inform_init request
2025-09-03 14:48:00,272 INFO    MainThread:14035 [wandb_init.py:init():865] backend started and connected
2025-09-03 14:48:00,273 INFO    MainThread:14035 [wandb_init.py:init():936] updated telemetry
2025-09-03 14:48:00,285 INFO    MainThread:14035 [wandb_init.py:init():960] communicating run to backend with 90.0 second timeout
2025-09-03 14:48:00,825 INFO    MainThread:14035 [wandb_init.py:init():1011] starting run threads in backend
2025-09-03 14:48:00,867 INFO    MainThread:14035 [wandb_run.py:_console_start():2494] atexit reg
2025-09-03 14:48:00,867 INFO    MainThread:14035 [wandb_run.py:_redirect():2342] redirect: wrap_raw
2025-09-03 14:48:00,867 INFO    MainThread:14035 [wandb_run.py:_redirect():2411] Wrapping output streams.
2025-09-03 14:48:00,867 INFO    MainThread:14035 [wandb_run.py:_redirect():2434] Redirects installed.
2025-09-03 14:48:00,869 INFO    MainThread:14035 [wandb_init.py:init():1057] run started, returning control to user process
2025-09-03 14:48:01,510 INFO    MainThread:14035 [wandb_run.py:_tensorboard_callback():1589] tensorboard callback: /Users/gurmannnpreet/Documents/CODING/rl2048/SAC_5, True
2025-09-03 14:54:44,097 INFO    wandb-AsyncioManager-main:14035 [service_client.py:_forward_responses():84] Reached EOF.
2025-09-03 14:54:44,097 INFO    wandb-AsyncioManager-main:14035 [mailbox.py:close():137] Closing mailbox, abandoning 1 handles.
2025-09-03 14:54:45,926 ERROR   wandb-AsyncioManager-main:14035 [asyncio_manager.py:fn_wrap_exceptions():183] Uncaught exception in run_soon callback.
Traceback (most recent call last):
  File "/Users/gurmannnpreet/Documents/CODING/rl2048/rlenv/lib/python3.13/site-packages/wandb/sdk/lib/asyncio_manager.py", line 181, in fn_wrap_exceptions
    await fn()
  File "/Users/gurmannnpreet/Documents/CODING/rl2048/rlenv/lib/python3.13/site-packages/wandb/sdk/lib/service/service_client.py", line 65, in _send_server_request
    await self._writer.drain()
  File "/opt/homebrew/Cellar/python@3.13/3.13.3_1/Frameworks/Python.framework/Versions/3.13/lib/python3.13/asyncio/streams.py", line 386, in drain
    await self._protocol._drain_helper()
  File "/opt/homebrew/Cellar/python@3.13/3.13.3_1/Frameworks/Python.framework/Versions/3.13/lib/python3.13/asyncio/streams.py", line 166, in _drain_helper
    raise ConnectionResetError('Connection lost')
ConnectionResetError: Connection lost
2025-09-03 14:54:45,932 ERROR   wandb-AsyncioManager-main:14035 [asyncio_manager.py:fn_wrap_exceptions():183] Uncaught exception in run_soon callback.
Traceback (most recent call last):
  File "/Users/gurmannnpreet/Documents/CODING/rl2048/rlenv/lib/python3.13/site-packages/wandb/sdk/lib/asyncio_manager.py", line 181, in fn_wrap_exceptions
    await fn()
  File "/Users/gurmannnpreet/Documents/CODING/rl2048/rlenv/lib/python3.13/site-packages/wandb/sdk/lib/service/service_client.py", line 65, in _send_server_request
    await self._writer.drain()
  File "/opt/homebrew/Cellar/python@3.13/3.13.3_1/Frameworks/Python.framework/Versions/3.13/lib/python3.13/asyncio/streams.py", line 386, in drain
    await self._protocol._drain_helper()
  File "/opt/homebrew/Cellar/python@3.13/3.13.3_1/Frameworks/Python.framework/Versions/3.13/lib/python3.13/asyncio/streams.py", line 166, in _drain_helper
    raise ConnectionResetError('Connection lost')
ConnectionResetError: Connection lost
2025-09-03 14:54:45,932 ERROR   wandb-AsyncioManager-main:14035 [asyncio_manager.py:fn_wrap_exceptions():183] Uncaught exception in run_soon callback.
Traceback (most recent call last):
  File "/Users/gurmannnpreet/Documents/CODING/rl2048/rlenv/lib/python3.13/site-packages/wandb/sdk/lib/asyncio_manager.py", line 181, in fn_wrap_exceptions
    await fn()
  File "/Users/gurmannnpreet/Documents/CODING/rl2048/rlenv/lib/python3.13/site-packages/wandb/sdk/lib/service/service_client.py", line 65, in _send_server_request
    await self._writer.drain()
  File "/opt/homebrew/Cellar/python@3.13/3.13.3_1/Frameworks/Python.framework/Versions/3.13/lib/python3.13/asyncio/streams.py", line 386, in drain
    await self._protocol._drain_helper()
  File "/opt/homebrew/Cellar/python@3.13/3.13.3_1/Frameworks/Python.framework/Versions/3.13/lib/python3.13/asyncio/streams.py", line 166, in _drain_helper
    raise ConnectionResetError('Connection lost')
ConnectionResetError: Connection lost
